<?xml version="1.0" ?>
<robot xmlns:xacro="http://ros.org/wiki/xacro" name="kawasaki_fs020n_manipulator">

<xacro:macro name="kawasaki_fs020n_manipulator" params="parent *origin">
    <material name="purple1">
        <color rgba="0.2 0.0 0.3 1.0"/>
    </material>
    <material name="purple2">
        <color rgba="0.3 0.0 0.4 1.0"/>
    </material>
    <material name="purple3">
        <color rgba="0.4 0.0 0.5 1.0"/>
    </material>
    <material name="purple4">
        <color rgba="0.5 0.0 0.6 1.0"/>
    </material>
    <material name="purple5">
        <color rgba="0.6 0.0 0.7 1.0"/>
    </material>
    <material name="purple6">
        <color rgba="0.7 0.0 0.8 1.0"/>
    </material>
    <material name="purple7">
        <color rgba="0.8 0.2 0.9 1.0"/>
    </material>
    <material name="purple8">
        <color rgba="0.8 0.5 0.9 1.0"/>
    </material>

    <link name="base_link">
        <visual>
            <origin rpy="0 0 0" xyz="0 0 0"/>
            <geometry>
                <mesh filename="package://robotic_system_description/mesh/manipulator/base_link.stl"/>
            </geometry>
            <material name="purple1" />
        </visual>
        <collision>
            <geometry>
                <mesh filename="package://robotic_system_description/mesh/manipulator/base_link.stl"/>
            </geometry>
        </collision>
    </link>

    <link name="link_1">
        <visual>
            <origin rpy="0 0 0" xyz="0 0 0"/>
            <geometry>
                <mesh filename="package://robotic_system_description/mesh/manipulator/link_1.stl"/>
            </geometry>
            <material name="purple2" />
        </visual>
        <collision>
            <geometry>
                <mesh filename="package://robotic_system_description/mesh/manipulator/link_1.stl"/>
            </geometry>
        </collision>
    </link>

    <link name="link_2">
        <visual>
            <origin rpy="0 0 0" xyz="0 0 0"/>
            <geometry>
                <mesh filename="package://robotic_system_description/mesh/manipulator/link_2.stl"/>
            </geometry>
            <material name="purple3" />
        </visual>
        <collision>
            <geometry>
                <mesh filename="package://robotic_system_description/mesh/manipulator/link_2.stl"/>
            </geometry>
        </collision>
    </link>

    <link name="link_3">
        <visual>
            <origin rpy="0 0 0" xyz="0 0 0"/>
            <geometry>
                <mesh filename="package://robotic_system_description/mesh/manipulator/link_3.stl"/>
            </geometry>
            <material name="purple4"/>
        </visual>
        <collision>
            <geometry>
                <mesh filename="package://robotic_system_description/mesh/manipulator/link_3.stl"/>
            </geometry>
        </collision>
    </link>

    <link name="link_4">
        <visual>
            <origin rpy="0 0 0" xyz="0 0 0"/>
            <geometry>
                <mesh filename="package://robotic_system_description/mesh/manipulator/link_4.stl"/>
            </geometry>
            <material name="purple5" />
        </visual>
        <collision>
            <geometry>
                <mesh filename="package://robotic_system_description/mesh/manipulator/link_4.stl"/>
            </geometry>
        </collision>
    </link>

    <link name="link_5">
        <visual>
            <origin rpy="0 0 0" xyz="0 0 0"/>
            <geometry>
                <mesh filename="package://robotic_system_description/mesh/manipulator/link_5.stl"/>
            </geometry>
            <material name="purple6" />
        </visual>
        <collision>
            <geometry>
                <mesh filename="package://robotic_system_description/mesh/manipulator/link_5.stl"/>
            </geometry>
        </collision>
    </link>

    <link name="link_6">
        <visual>
            <origin rpy="0 0 0" xyz="0 0 0"/>
            <geometry>
                <mesh filename="package://robotic_system_description/mesh/manipulator/link_6.stl"/>
            </geometry>
            <material name="purple7" />
        </visual>
        <collision>
            <geometry>
                <mesh filename="package://robotic_system_description/mesh/manipulator/link_6.stl"/>
            </geometry>
        </collision>
    </link>

    <joint name="base_joint" type="fixed">
        <parent link="${parent}"/>
        <child link="base_link"/>
        <xacro:insert_block name="origin" />
    </joint>

    <joint name="joint_0" type="revolute">
        <limit effort="1000.0" lower="-2.7925" upper="2.7925" velocity="0.5"/>
        <parent link="base_link"/>
        <child link="link_1"/>
        <origin xyz="0 0 1.13" rpy="3.1415926 0 0" />
        <axis xyz="0 0 1" />
    </joint>

    <joint name="joint_1" type="revolute">
        <limit effort="1000.0" lower="-1.8326" upper="2.4435" velocity="0.5"/>
        <parent link="link_1"/>
        <child link="link_2"/>
        <origin xyz="0.035 -0.150 -0.310" rpy="3.1415926 1.570796 0" />
        <axis xyz="0 0 1" />
    </joint>

    <joint name="joint_2" type="revolute">
        <limit effort="1000.0" lower="-2.7053" upper="2.0944" velocity="0.5"/>
        <parent link="link_2"/>
        <child link="link_3"/>
        <origin xyz="0.8 0 0" rpy="3.1415926 0 0" />
        <axis xyz="0 0 1" />
    </joint>

    <joint name="joint_3" type="revolute">
        <limit effort="1000.0" lower="-4.7124" upper="4.7124" velocity="0.5"/>
        <parent link="link_3"/>
        <child link="link_4"/>
        <origin xyz="0.225 0.06 -0.042" rpy="0 1.570796 0" />
        <axis xyz="0 0 1" />
    </joint>

    <joint name="joint_4" type="revolute">
        <limit effort="1000.0" lower="-2" upper="2" velocity="0.5"/>
        <parent link="link_4"/>
        <child link="link_5"/>
        <origin xyz="0 0 0.475" rpy="0 -1.570796 0" />
        <axis xyz="0 0 1" />
    </joint>

    <joint name="joint_5" type="revolute">
        <limit effort="1000.0" lower="-6.2832" upper="6.2832" velocity="0.5"/>
        <parent link="link_5"/>
        <child link="link_6"/>
        <origin xyz="0.0525 0 0" rpy="3.1415926 -1.570796 0" />
        <axis xyz="0 0 1" />
    </joint>
</xacro:macro>

</robot>


