<?xml version="1.0" ?>
<!-- =================================================================================== -->
<!-- |    This document was autogenerated by xacro from robotic_system.urdf.xacro      | -->
<!-- |    EDITING THIS FILE BY HAND IS NOT RECOMMENDED                                 | -->
<!-- =================================================================================== -->
<robot name="robotic_system">
  <material name="orange_color">
    <color rgba="1 0.6 0.3 1"/>
  </material>
  <material name="yellow">
    <color rgba="0.8 0.7 0.5 1"/>
  </material>
  <material name="grey">
    <color rgba="0.3 0.3 0.3 1"/>
  </material>
  <material name="blue">
    <color rgba="0.2 0.2 0.9 1"/>
  </material>
  <material name="black">
    <color rgba="0 0 0 1"/>
  </material>
  <link name="robotic_system"/>
  <material name="purple1">
    <color rgba="0.2 0.0 0.3 1.0"/>
  </material>
  <material name="purple2">
    <color rgba="0.3 0.0 0.4 1.0"/>
  </material>
  <material name="purple3">
    <color rgba="0.4 0.0 0.5 1.0"/>
  </material>
  <material name="purple4">
    <color rgba="0.5 0.0 0.6 1.0"/>
  </material>
  <material name="purple5">
    <color rgba="0.6 0.0 0.7 1.0"/>
  </material>
  <material name="purple6">
    <color rgba="0.7 0.0 0.8 1.0"/>
  </material>
  <material name="purple7">
    <color rgba="0.8 0.2 0.9 1.0"/>
  </material>
  <material name="purple8">
    <color rgba="0.8 0.5 0.9 1.0"/>
  </material>
  <link name="base_link">
    <visual>
      <origin rpy="0 0 0" xyz="0 0 0"/>
      <geometry>
        <mesh filename="package://robotic_system_description/mesh/manipulator/base_link.stl"/>
      </geometry>
      <material name="purple1"/>
    </visual>
    <collision>
      <geometry>
        <mesh filename="package://robotic_system_description/mesh/manipulator/base_link.stl"/>
      </geometry>
    </collision>
  </link>
  <link name="link_1">
    <visual>
      <origin rpy="0 0 0" xyz="0 0 0"/>
      <geometry>
        <mesh filename="package://robotic_system_description/mesh/manipulator/link_1.stl"/>
      </geometry>
      <material name="purple2"/>
    </visual>
    <collision>
      <geometry>
        <mesh filename="package://robotic_system_description/mesh/manipulator/link_1.stl"/>
      </geometry>
    </collision>
  </link>
  <link name="link_2">
    <visual>
      <origin rpy="0 0 0" xyz="0 0 0"/>
      <geometry>
        <mesh filename="package://robotic_system_description/mesh/manipulator/link_2.stl"/>
      </geometry>
      <material name="purple3"/>
    </visual>
    <collision>
      <geometry>
        <mesh filename="package://robotic_system_description/mesh/manipulator/link_2.stl"/>
      </geometry>
    </collision>
  </link>
  <link name="link_3">
    <visual>
      <origin rpy="0 0 0" xyz="0 0 0"/>
      <geometry>
        <mesh filename="package://robotic_system_description/mesh/manipulator/link_3.stl"/>
      </geometry>
      <material name="purple4"/>
    </visual>
    <collision>
      <geometry>
        <mesh filename="package://robotic_system_description/mesh/manipulator/link_3.stl"/>
      </geometry>
    </collision>
  </link>
  <link name="link_4">
    <visual>
      <origin rpy="0 0 0" xyz="0 0 0"/>
      <geometry>
        <mesh filename="package://robotic_system_description/mesh/manipulator/link_4.stl"/>
      </geometry>
      <material name="purple5"/>
    </visual>
    <collision>
      <geometry>
        <mesh filename="package://robotic_system_description/mesh/manipulator/link_4.stl"/>
      </geometry>
    </collision>
  </link>
  <link name="link_5">
    <visual>
      <origin rpy="0 0 0" xyz="0 0 0"/>
      <geometry>
        <mesh filename="package://robotic_system_description/mesh/manipulator/link_5.stl"/>
      </geometry>
      <material name="purple6"/>
    </visual>
    <collision>
      <geometry>
        <mesh filename="package://robotic_system_description/mesh/manipulator/link_5.stl"/>
      </geometry>
    </collision>
  </link>
  <link name="link_6">
    <visual>
      <origin rpy="0 0 0" xyz="0 0 0"/>
      <geometry>
        <mesh filename="package://robotic_system_description/mesh/manipulator/link_6.stl"/>
      </geometry>
      <material name="purple7"/>
    </visual>
    <collision>
      <geometry>
        <mesh filename="package://robotic_system_description/mesh/manipulator/link_6.stl"/>
      </geometry>
    </collision>
  </link>
  <joint name="base_joint" type="fixed">
    <parent link="robotic_system"/>
    <child link="base_link"/>
    <origin rpy="0 0 0" xyz="0 0 0"/>
  </joint>
  <joint name="joint_0" type="revolute">
    <limit effort="1000.0" lower="-2.7925" upper="2.7925" velocity="0.5"/>
    <parent link="base_link"/>
    <child link="link_1"/>
    <origin rpy="3.1415926 0 0" xyz="0 0 1.13"/>
    <axis xyz="0 0 1"/>
  </joint>
  <joint name="joint_1" type="revolute">
    <limit effort="1000.0" lower="-1.8326" upper="2.4435" velocity="0.5"/>
    <parent link="link_1"/>
    <child link="link_2"/>
    <origin rpy="3.1415926 1.570796 0" xyz="0.035 -0.150 -0.310"/>
    <axis xyz="0 0 1"/>
  </joint>
  <joint name="joint_2" type="revolute">
    <limit effort="1000.0" lower="-2.7053" upper="2.0944" velocity="0.5"/>
    <parent link="link_2"/>
    <child link="link_3"/>
    <origin rpy="3.1415926 0 0" xyz="0.8 0 0"/>
    <axis xyz="0 0 1"/>
  </joint>
  <joint name="joint_3" type="revolute">
    <limit effort="1000.0" lower="-4.7124" upper="4.7124" velocity="0.5"/>
    <parent link="link_3"/>
    <child link="link_4"/>
    <origin rpy="0 1.570796 0" xyz="0.225 0.06 -0.042"/>
    <axis xyz="0 0 1"/>
  </joint>
  <joint name="joint_4" type="revolute">
    <limit effort="1000.0" lower="-2" upper="2" velocity="0.5"/>
    <parent link="link_4"/>
    <child link="link_5"/>
    <origin rpy="0 -1.570796 0" xyz="0 0 0.475"/>
    <axis xyz="0 0 1"/>
  </joint>
  <joint name="joint_5" type="revolute">
    <limit effort="1000.0" lower="-6.2832" upper="6.2832" velocity="0.5"/>
    <parent link="link_5"/>
    <child link="link_6"/>
    <origin rpy="3.1415926 -1.570796 0" xyz="0.0525 0 0"/>
    <axis xyz="0 0 1"/>
  </joint>
  <joint name="fts_joint" type="fixed">
    <parent link="link_6"/>
    <child link="fts_link"/>
    <origin rpy="0 0 0" xyz="0 0 0.045"/>
  </joint>
  <joint name="fts_tool_joint" type="fixed">
    <origin rpy="0 0 0" xyz="0 0 0.033"/>
    <parent link="fts_link"/>
    <child link="fts_tool"/>
  </joint>
  <joint name="fts_frame_joint" type="fixed">
    <origin rpy="0 0 3.1416" xyz="0 0 0"/>
    <parent link="fts_tool"/>
    <child link="fts_frame"/>
  </joint>
  <link name="fts_link">
    <inertial>
      <mass value="1.2"/>
      <origin xyz="0 0 0"/>
      <inertia ixx="1.0" ixy="0.0" ixz="0.0" iyy="1.0" iyz="0.0" izz="1.0"/>
    </inertial>
    <visual>
      <origin rpy="0 0 0" xyz="0.0 0 0.0"/>
      <geometry>
        <mesh filename="package://robotic_system_description/mesh/fts/fts.stl" scale="1.1 1.1 1.1"/>
      </geometry>
      <material name="orange_color"/>
    </visual>
    <collision>
      <origin rpy="0 0 0" xyz="0.0 0 0.0"/>
      <geometry>
        <mesh filename="package://robotic_system_description/mesh/fts/fts.stl" scale="1.1 1.1 1.1"/>
      </geometry>
    </collision>
  </link>
  <link name="fts_tool"/>
  <link name="fts_frame"/>
  <joint name="gripper_adapter_joint" type="fixed">
    <parent link="fts_frame"/>
    <child link="gripper_adapter_link"/>
    <origin rpy="0 0 0" xyz="0 0 0"/>
  </joint>
  <joint name="gripper_adapter_tool_joint" type="fixed">
    <origin rpy="0 0 0" xyz="0 0 0.03"/>
    <parent link="gripper_adapter_link"/>
    <child link="gripper_adapter_tool"/>
  </joint>
  <link name="gripper_adapter_link">
    <inertial>
      <mass value="1.2"/>
      <origin xyz="0 0 0"/>
      <inertia ixx="1.0" ixy="0.0" ixz="0.0" iyy="1.0" iyz="0.0" izz="1.0"/>
    </inertial>
    <visual>
      <origin rpy="0 0 0" xyz="0.0 0 0.0"/>
      <geometry>
        <mesh filename="package://robotic_system_description/mesh/gripper_adapter/gripper_adapter.stl" scale="1 1 1"/>
      </geometry>
      <material name="orange_color"/>
    </visual>
    <collision>
      <origin rpy="0 0 0" xyz="0.0 0 0.0"/>
      <geometry>
        <mesh filename="package://robotic_system_description/mesh/gripper_adapter/gripper_adapter.stl" scale="1 1 1"/>
      </geometry>
    </collision>
  </link>
  <link name="gripper_adapter_tool"/>
  <!-- PALM LINK -->
  <link name="palm_link">
    <inertial>
      <mass value="1.2"/>
      <origin xyz="0 0 0"/>
      <inertia ixx="1.0" ixy="0.0" ixz="0.0" iyy="1.0" iyz="0.0" izz="1.0"/>
    </inertial>
    <visual>
      <origin rpy="0 0 0" xyz="0.0 0 0"/>
      <geometry>
        <mesh filename="package://robotic_system_description/mesh/wsg_50/palm.stl" scale="1 1 1"/>
      </geometry>
      <material name="yellow"/>
    </visual>
    <collision>
      <origin rpy="0 0 0" xyz="0.0 0 0"/>
      <geometry>
        <mesh filename="package://robotic_system_description/mesh/wsg_50/palm_collision.stl" scale="1 1 1"/>
      </geometry>
    </collision>
  </link>
  <!-- GRIPPER LEFT -->
  <link name="gripper_left">
    <inertial>
      <mass value="0.1"/>
      <origin xyz="0 0 0"/>
      <inertia ixx="1.0" ixy="0.0" ixz="0.0" iyy="1.0" iyz="0.0" izz="1.0"/>
    </inertial>
    <visual>
      <origin rpy="0 0 0" xyz="0.0 0 0"/>
      <geometry>
        <mesh filename="package://robotic_system_description/mesh/wsg_50/gripper.stl" scale="0.001 0.001 0.001"/>
      </geometry>
      <material name="grey"/>
    </visual>
    <collision>
      <origin rpy="0 0 0" xyz="0 0 0"/>
      <geometry>
        <mesh filename="package://robotic_system_description/mesh/wsg_50/gripper.stl" scale="0.001 0.001 0.001"/>
      </geometry>
    </collision>
  </link>
  <!-- FINGER LEFT -->
  <link name="finger_left">
    <inertial>
      <mass value="0.1"/>
      <origin xyz="0 0 0"/>
      <inertia ixx="1.0" ixy="0.0" ixz="0.0" iyy="1.0" iyz="0.0" izz="1.0"/>
    </inertial>
    <visual>
      <origin rpy="0 0 0" xyz="0.0 0 0"/>
      <geometry>
        <mesh filename="package://robotic_system_description/mesh/wsg_50/wsg50_original.stl" scale="1 1 1"/>
      </geometry>
      <material name="black"/>
    </visual>
    <collision>
      <origin rpy="0 0 0" xyz="0 0 0"/>
      <geometry>
        <mesh filename="package://robotic_system_description/mesh/wsg_50/wsg50_original.stl" scale="1 1 1"/>
      </geometry>
    </collision>
  </link>
  <!-- GRIPPER RIGHT -->
  <link name="gripper_right">
    <inertial>
      <mass value="0.1"/>
      <origin xyz="0 0 0"/>
      <inertia ixx="1.0" ixy="0.0" ixz="0.0" iyy="1.0" iyz="0.0" izz="1.0"/>
    </inertial>
    <visual>
      <origin rpy="0 0 0" xyz="0.0 0 0"/>
      <geometry>
        <mesh filename="package://robotic_system_description/mesh/wsg_50/gripper.stl" scale="0.001 0.001 0.001"/>
      </geometry>
      <material name="grey"/>
    </visual>
    <collision>
      <origin rpy="0 0 0" xyz="0 0 0"/>
      <geometry>
        <mesh filename="package://robotic_system_description/mesh/wsg_50/gripper.stl" scale="0.001 0.001 0.001"/>
      </geometry>
    </collision>
  </link>
  <!-- FINGER RIGHT -->
  <link name="finger_right">
    <inertial>
      <mass value="0.1"/>
      <origin xyz="0 0 0"/>
      <inertia ixx="1.0" ixy="0.0" ixz="0.0" iyy="1.0" iyz="0.0" izz="1.0"/>
    </inertial>
    <visual>
      <origin rpy="0 0 0" xyz="0.0 0 0"/>
      <geometry>
        <mesh filename="package://robotic_system_description/mesh/wsg_50/wsg50_original.stl" scale="1 1 1"/>
      </geometry>
      <material name="black"/>
    </visual>
    <collision>
      <origin rpy="0 0 0" xyz="0 0 0"/>
      <geometry>
        <mesh filename="package://robotic_system_description/mesh/wsg_50/wsg50_original.stl" scale="1 1 1"/>
      </geometry>
    </collision>
  </link>
  <link name="palm_revolute">
    <inertial>
      <mass value="0.00001"/>
      <origin xyz="0 0 0"/>
      <inertia ixx="0" ixy="0.0" ixz="0.0" iyy="0" iyz="0.0" izz=".0"/>
    </inertial>
    <visual>
      <origin rpy="0 0 0" xyz="0.0 0 0"/>
      <geometry>
        <box size="0.00001 0.00001 0.00001"/>
      </geometry>
      <material name="black"/>
    </visual>
    <collision>
      <origin rpy="0 0 0" xyz="0 0 0"/>
      <geometry>
        <box size="0.00001 0.00001 0.00001"/>
      </geometry>
    </collision>
  </link>
  <joint name="palm_joint" type="fixed">
    <parent link="gripper_adapter_tool"/>
    <child link="palm_link"/>
    <origin rpy="0 0 0" xyz="0 0 0"/>
  </joint>
  <joint name="palm_revolute" type="revolute">
    <origin rpy="0 0 0" xyz="0 0 0"/>
    <parent link="palm_link"/>
    <child link="palm_revolute"/>
    <axis xyz="0 0 1"/>
    <limit effort="100" lower="0" upper="6.283185307179586" velocity="100"/>
  </joint>
  <!-- palm_joint_gripper_lower = multiplier * palm_revolute_lower + offset -->
  <!-- palm_joint_gripper_upper = multiplier * palm_revolute_upper + offset -->
  <!-- Params for left joint -->
  <!-- Params for right joint -->
  <joint name="palm_joint_gripper_left" type="prismatic">
    <!-- <limit effort="1.0" lower="-0.055" upper="-0.0032" velocity="1.0"/> -->
    <limit effort="1.0" lower="-0.055" upper="-0.005" velocity="1.0"/>
    <origin rpy="0 0 0" xyz="0 0 0"/>
    <parent link="palm_link"/>
    <child link="gripper_left"/>
    <axis xyz="1 0 0"/>
    <mimic joint="palm_revolute" multiplier="-0.0079" offset="-0.005"/>
  </joint>
  <joint name="palm_joint_gripper_right" type="prismatic">
    <!-- <limit effort="1.0" lower="0.0032" upper="0.055" velocity="1.0"/> -->
    <limit effort="1.0" lower="0.055" upper="0.005" velocity="1.0"/>
    <origin rpy="0 0 3.14159" xyz="0 0 0"/>
    <parent link="palm_link"/>
    <child link="gripper_right"/>
    <axis xyz="-1 0 0"/>
    <mimic joint="palm_revolute" multiplier="0.0079" offset="0.005"/>
  </joint>
  <joint name="gripper_joint_finger_left" type="fixed">
    <origin rpy="0 0 0" xyz="0 0 0.023"/>
    <parent link="gripper_left"/>
    <child link="finger_left"/>
    <axis xyz="1 0 0"/>
  </joint>
  <joint name="gripper_joint_finger_right" type="fixed">
    <origin rpy="0 0 0" xyz="0 0 0.023"/>
    <parent link="gripper_right"/>
    <child link="finger_right"/>
    <axis xyz="1 0 0"/>
  </joint>
  <link name="zed_left_camera">
    <visual>
      <origin rpy="0 1.57 0" xyz="0 0 0"/>
      <geometry>
        <cylinder length=".031" radius="0.007"/>
      </geometry>
      <material name="dark_grey">
        <color rgba="0.1 0.1 0.1 1"/>
      </material>
    </visual>
    <collision>
      <origin rpy="0 1.57 0" xyz="0 0 0"/>
      <geometry>
        <cylinder length=".031" radius="0.007"/>
      </geometry>
    </collision>
  </link>
  <link name="zed_center">
    <visual>
      <origin rpy="0 0 0" xyz="0 0 0"/>
      <geometry>
        <mesh filename="package://robotic_system_description/mesh/zed/zed.stl"/>
      </geometry>
      <material name="light_grey">
        <color rgba="0.8 0.8 0.8 0.8"/>
      </material>
    </visual>
    <collision>
      <origin rpy="0 0 0" xyz="0.0 0 0"/>
      <geometry>
        <mesh filename="package://robotic_system_description/mesh/zed/zed.stl" scale="1 1 1"/>
      </geometry>
    </collision>
  </link>
  <link name="zed_right_camera">
    <visual>
      <origin rpy="0 1.57 0" xyz="0 0 0"/>
      <geometry>
        <cylinder length=".031" radius="0.007"/>
      </geometry>
      <material name="dark_grey">
        <color rgba="0.1 0.1 0.1 1"/>
      </material>
    </visual>
    <collision>
      <origin rpy="0 1.57 0" xyz="0 0 0"/>
      <geometry>
        <cylinder length=".031" radius="0.007"/>
      </geometry>
    </collision>
  </link>
  <joint name="zed_joint" type="fixed">
    <parent link="gripper_adapter_link"/>
    <child link="zed_left_camera"/>
    <origin rpy="1.57 -1.57 0" xyz="-0.06 0.06 0.087"/>
  </joint>
  <!-- The distance between two cameras is 120 mm -->
  <joint name="zed_center_joint" type="fixed">
    <parent link="zed_left_camera"/>
    <child link="zed_center"/>
    <origin rpy="0 0 0" xyz="0 -0.06 0"/>
  </joint>
  <joint name="zed_right_camera_joint" type="fixed">
    <parent link="zed_left_camera"/>
    <child link="zed_right_camera"/>
    <origin rpy="0 0 0" xyz="0 -0.12 0"/>
  </joint>
</robot>

